<?xml version="1.0" ?>
<robot name="spot" xmlns:xacro="http://www.ros.org/wiki/xacro">
<!-- Body -->
    <link name="body">
        <visual>
            <geometry>
                <mesh filename="package://rs_description/meshes/body.dae" />
            </geometry>
        </visual>
        <collision>
            <geometry>
                <mesh filename="package://rs_description/meshes/body_collision.stl" />
            </geometry>
        </collision>
        <inertial>
             <mass value="16.25" />
             <inertia  ixx="0.085" ixy="0.0"  ixz="0.0"  iyy="1.045"  iyz="0.0"  izz="1.042" />
    	</inertial>
    </link>
<!-- Base link -->
    <link name="base_link"/>
    <joint name="base_link_joint" type="fixed">
        <origin xyz="0 0 0" rpy="0 0 0" />
        <parent link="body" />
        <child link="base_link" />
    </joint>
<!-- Front rail -->
    <link name="front_rail"/>
    <joint name="front_rail_joint" type="fixed">
        <origin xyz="0.223 0 0.04505" rpy="0 0 0" />
        <parent link="body" />
        <child link="front_rail" />
    </joint>
<!-- Rear rail -->
    <link name="rear_rail"/>
    <joint name="rear_rail_joint" type="fixed">
        <origin xyz="-0.223 0 0.04505" rpy="0 0 0" />
        <parent link="body" />
        <child link="rear_rail" />
    </joint> 
<!-- front_left_hip -->
    <link name="front_left_hip">
        <visual>
            <geometry>
                <mesh filename="package://rs_description/meshes/front_left_hip.dae" />
            </geometry>
        </visual>
        <collision>
            <geometry>
                <mesh filename="package://rs_description/meshes/front_left_hip_collision.stl" />
            </geometry>
        </collision>
        <inertial>
            <mass value="1.5" />
    	    <inertia  ixx="0.0605" ixy="0.0"  ixz="0.0"  iyy="0.0"  iyz="0.0"  izz="0.0" />
    	</inertial>
    </link>
    
    <joint name="front_left_hip_x" type="revolute">
        <origin xyz="0.29785 0.05500 0.00000" rpy="0 0 0" />
        <axis xyz="1 0 0" />
        <parent link="body" />
	<child link="front_left_hip" />
	<dynamics damping="0.1" friction="0.1"/>
        <limit effort="1000" velocity="1000.00" lower="-0.78539816339744827899" upper="0.78539816339744827899" />
    </joint>
    
    <transmission name="front_left_hip_x_trans">
	  <type>transmission_interface/SimpleTransmission</type>
	  <joint name="front_left_hip_x">
          	<hardwareInterface>EffortJointInterface</hardwareInterface>
          </joint>
	  <actuator name="front_left_hip_x">
          	<mechanicalReduction>50</mechanicalReduction>
          	<hardwareInterface>EffortJointInterface</hardwareInterface>
	  </actuator>
    </transmission>
<!-- front_left_upper_leg -->
    <link name="front_left_upper_leg">
        <visual>
            <geometry>
                <mesh filename="package://rs_description/meshes/front_left_upper_leg.dae" />
            </geometry>
        </visual>
        <collision>
            <geometry>
                <mesh filename="package://rs_description/meshes/front_left_upper_leg_collision.stl" />
            </geometry>
        </collision>
        <inertial>
            <mass value="1.5" />
    	    <inertia  ixx="0.0" ixy="0.0"  ixz="0.0"  iyy="0.05"  iyz="0.0"  izz="0.0" />
    	</inertial>
    </link>
    
    <joint name="front_left_hip_y" type="revolute">
        <origin xyz="0.0 0.110945 0.0" rpy="0 0 0" />
        <axis xyz="0 1 0" />
        <parent link="front_left_hip" />
	<child link="front_left_upper_leg" />
	<dynamics damping="0.1" friction="0.1"/>
        <limit effort="1000" velocity="1000.00" lower="-0.89884456477707963539" upper="2.2951079663725435509" />
    </joint>

    <transmission name="front_left_hip_y_trans">
	  <type>transmission_interface/SimpleTransmission</type>
	  <joint name="front_left_hip_y">
          	<hardwareInterface>EffortJointInterface</hardwareInterface>
          </joint>
	  <actuator name="front_left_hip_y">
          	<mechanicalReduction>50</mechanicalReduction>
          	<hardwareInterface>EffortJointInterface</hardwareInterface>
	  </actuator>
    </transmission>
<!-- front_left_lower_leg -->   
    <link name="front_left_lower_leg">
        <visual>
            <geometry>
                <mesh filename="package://rs_description/meshes/front_left_lower_leg.dae" />
            </geometry>
        </visual>
        <collision name="front_left_lower_leg_fixed_joint_lump__front_bump_sensor">
            <geometry>
                <mesh filename="package://rs_description/meshes/front_left_lower_leg_collision.stl" />
            </geometry>
        </collision>
        <inertial>right
            <mass value="1.0" />
    	    <inertia  ixx="0.0" ixy="0.0"  ixz="0.0"  iyy="0.045"  iyz="0.0"  izz="0.0" />
    	</inertial>
    </link>

    <joint name="front_left_knee" type="revolute">
        <origin xyz="0.025 0.000 -0.3205" rpy="0 0 0" />
        <axis xyz="0 1 0" />
        <parent link="front_left_upper_leg" />
        <child link="front_left_lower_leg" />
        <dynamics damping="0.1" friction="0.1"/>
        <limit effort="1000" velocity="1000.00" lower="-2.7929" upper="-0.254801" />
    </joint>

     <!-- Contact Sensor -->
  <gazebo reference="front_left_lower_leg">
    <sensor name="front_left_lower_leg_contactsensor_sensor" type="contact">
      <always_on>true</always_on>
      <contact>
        <collision>front_left_lower_leg_fixed_joint_lump__front_bump_sensor_collision</collision>
      </contact>
      <plugin filename="libgazebo_ros_bumper.so" name="front_left_lower_leg_plugin">
        <bumperTopicName>front_left_lower_leg_contact</bumperTopicName>
        <frameName>front_left_lower_leg</frameName>
      </plugin>
    </sensor>
  </gazebo>

    <transmission name="front_left_knee_trans">
	  <type>transmission_interface/SimpleTransmission</type>
	  <joint name="front_left_knee">
          	<hardwareInterface>EffortJointInterface</hardwareInterface>
          </joint>
	  <actuator name="front_left_knee">
          	<mechanicalReduction>50</mechanicalReduction>
          	<hardwareInterface>EffortJointInterface</hardwareInterface>
	  </actuator>
    </transmission>
<!--front_right_hip-->
    <link name="front_right_hip">
        <visual>
            <geometry>
                <mesh filename="package://rs_description/meshes/front_right_hip.dae" />
            </geometry>
        </visual>
        <collision>
            <geometry>
                <mesh filename="package://rs_description/meshes/front_right_hip_collision.stl" />
            </geometry>
        </collision>
        <inertial>
            <mass value="1.5" />
    	    <inertia  ixx="0.0605" ixy="0.0"  ixz="0.0"  iyy="0.0"  iyz="0.0"  izz="0.0" />
    	</inertial>
    </link>

    <joint name="front_right_hip_x" type="revolute">
        <origin xyz="0.29785 -0.05500 0.00000" rpy="0 0 0" />
        <axis xyz="1 0 0" />
        <parent link="body" />
        <child link="front_right_hip" />
        <dynamics damping="0.1" friction="0.1"/>
        <limit effort="1000" velocity="1000.00" lower="-0.78539816339744827899" upper="0.78539816339744827899" />
    </joint>

    <transmission name="front_right_hip_x_trans">
	  <type>transmission_interface/SimpleTransmission</type>
	  <joint name="front_right_hip_x">
          	<hardwareInterface>EffortJointInterface</hardwareInterface>
          </joint>
	  <actuator name="front_right_hip_x">
          	<mechanicalReduction>50</mechanicalReduction>
          	<hardwareInterface>EffortJointInterface</hardwareInterface>
	  </actuator>
    </transmission>
<!-- front_right_upper_leg -->
    <link name="front_right_upper_leg">
        <visual>
            <geometry>
                <mesh filename="package://rs_description/meshes/front_right_upper_leg.dae" />
            </geometry>
        </visual>
        <collision>
            <geometry>
                <mesh filename="package://rs_description/meshes/front_right_upper_leg_collision.stl" />
            </geometry>
        </collision>
        <inertial>
            <mass value="1.5" />
    	    <inertia  ixx="0.0" ixy="0.0"  ixz="0.0"  iyy="0.05"  iyz="0.0"  izz="0.0" />
    	</inertial>
    </link>

    <joint name="front_right_hip_y" type="revolute">
        <origin xyz="0.0 -0.110945 0.0" rpy="0 0 0" />
        <axis xyz="0 1 0" />
        <parent link="front_right_hip" />
        <child link="front_right_upper_leg" />
        <dynamics damping="0.1" friction="0.1"/>
        <limit effort="1000" velocity="1000.00" lower="-0.89884456477707963539" upper="2.2951079663725435509" />
    </joint>

    <transmission name="front_right_hip_y_trans">
	  <type>transmission_interface/SimpleTransmission</type>
	  <joint name="front_right_hip_y">
          	<hardwareInterface>EffortJointInterface</hardwareInterface>
          </joint>
	  <actuator name="front_right_hip_y">
          	<mechanicalReduction>50</mechanicalReduction>
          	<hardwareInterface>EffortJointInterface</hardwareInterface>
	  </actuator>
    </transmission>
<!-- front_right_lower_leg -->
    <link name="front_right_lower_leg">
        <visual>
            <geometry>
                <mesh filename="package://rs_description/meshes/front_right_lower_leg.dae" />
            </geometry>
        </visual>
        <collision name="front_right_lower_leg_fixed_joint_lump__front_bump_sensor">
            <geometry>
                <mesh filename="package://rs_description/meshes/front_right_lower_leg_collision.stl" />
            </geometry>
        </collision>
        <inertial>
            <mass value="1.0" />
    	    <inertia  ixx="0.0" ixy="0.0"  ixz="0.0"  iyy="0.045"  iyz="0.0"  izz="0.0" />
    	</inertial>
    </link>

    <joint name="front_right_knee" type="revolute">
        <origin xyz="0.025 0.000 -0.3205" rpy="0 0 0" />
        <axis xyz="0 1 0" />
        <parent link="front_right_upper_leg" />
        <child link="front_right_lower_leg" />
        <dynamics damping="0.1" friction="0.1"/>
        <limit effort="1000" velocity="1000.00" lower="-2.7929" upper="-0.247563" />
    </joint>

     <!-- Contact Sensor -->
  <gazebo reference="front_right_lower_leg">
    <sensor name="front_right_lower_leg_contactsensor_sensor" type="contact">
      <always_on>true</always_on>
      <contact>
        <collision>front_right_lower_leg_fixed_joint_lump__front_bump_sensor_collision</collision>
      </contact>
      <plugin filename="libgazebo_ros_bumper.so" name="front_right_lower_leg_plugin">
        <bumperTopicName>front_right_lower_leg_contact</bumperTopicName>
        <frameName>front_right_lower_leg</frameName>
      </plugin>
    </sensor>
  </gazebo>

    <transmission name="front_right_knee_trans">
	  <type>transmission_interface/SimpleTransmission</type>
	  <joint name="front_right_knee">
          	<hardwareInterface>EffortJointInterface</hardwareInterface>
          </joint>
	  <actuator name="front_right_knee">
          	<mechanicalReduction>50</mechanicalReduction>
          	<hardwareInterface>EffortJointInterface</hardwareInterface>
	  </actuator>
    </transmission>
<!-- rear_left_hip -->
   <link name="rear_left_hip">
        <visual>
            <geometry>
                <mesh filename="package://rs_description/meshes/rear_left_hip.dae" />
            </geometry>
        </visual>
        <collision>
            <geometry>
                <mesh filename="package://rs_description/meshes/rear_left_hip_collision.stl" />
            </geometry>
        </collision>
        <inertial>
            <mass value="1.5" />
    	    <inertia  ixx="0.0605" ixy="0.0"  ixz="0.0"  iyy="0.0"  iyz="0.0"  izz="0.0" />
    	</inertial>
    </link>

    <joint name="rear_left_hip_x" type="revolute">
        <origin xyz="-0.29785 0.05500 0.00000" rpy="0 0 0" />
        <axis xyz="1 0 0" />
        <parent link="body" />
        <child link="rear_left_hip" />
        <dynamics damping="0.1" friction="0.1"/>
        <limit effort="1000" velocity="1000.00" lower="-0.78539816339744827899" upper="0.78539816339744827899" />
    </joint>

    <transmission name="rear_left_hip_x_trans">
	  <type>transmission_interface/SimpleTransmission</type>
	  <joint name="rear_left_hip_x">
          	<hardwareInterface>EffortJointInterface</hardwareInterface>
          </joint>
	  <actuator name="rear_left_hip_x">
          	<mechanicalReduction>50</mechanicalReduction>
          	<hardwareInterface>EffortJointInterface</hardwareInterface>
	  </actuator>
    </transmission>
<!-- rear_left_upper_leg -->
    <link name="rear_left_upper_leg">
        <visual>
            <geometry>
                <mesh filename="package://rs_description/meshes/rear_left_upper_leg.dae" />
            </geometry>
        </visual>
        <collision>
            <geometry>
                <mesh filename="package://rs_description/meshes/rear_left_upper_leg_collision.stl" />
            </geometry>
        </collision>
        <inertial>
           <mass value="1.5" />
    	   <inertia  ixx="0.0" ixy="0.0"  ixz="0.0"  iyy="0.05"  iyz="0.0"  izz="0.0" />
    	</inertial>
    </link>

    <joint name="rear_left_hip_y" type="revolute">
        <origin xyz="0.0 0.110945 0.0" rpy="0 0 0" />
        <axis xyz="0 1 0" />
        <parent link="rear_left_hip" />
        <child link="rear_left_upper_leg" />
        <dynamics damping="0.1" friction="0.1"/>
        <limit effort="1000" velocity="1000.00" lower="-0.89884456477707963539" upper="2.2951079663725435509" />
    </joint>

    <transmission name="rear_left_hip_y_trans">
	  <type>transmission_interface/SimpleTransmission</type>
	  <joint name="rear_left_hip_y">
          	<hardwareInterface>EffortJointInterface</hardwareInterface>
          </joint>
	  <actuator name="rear_left_hip_y">
          	<mechanicalReduction>50</mechanicalReduction>
          	<hardwareInterface>EffortJointInterface</hardwareInterface>
	  </actuator>
    </transmission>
<!-- rear_left_lower_leg -->
    <link name="rear_left_lower_leg">
        <visual>
            <geometry>
                <mesh filename="package://rs_description/meshes/rear_left_lower_leg.dae" />
            </geometry>
        </visual>
        <collision name="rear_left_lower_leg_fixed_joint_lump__rear_bump_sensor">
            <geometry>
                <mesh filename="package://rs_description/meshes/rear_left_lower_leg_collision.stl" />
            </geometry>
        </collision>
        <inertial>
            <mass value="1.0" />
    	    <inertia  ixx="0.0" ixy="0.0"  ixz="0.0"  iyy="0.045"  iyz="0.0"  izz="0.0" />
    	</inertial>
    </link>

    <joint name="rear_left_knee" type="revolute">
        <origin xyz="0.025 0.000 -0.3205" rpy="0 0 0" />
        <axis xyz="0 1 0" />
        <parent link="rear_left_upper_leg" />
        <child link="rear_left_lower_leg" />
        <dynamics damping="0.1" friction="0.1"/>
        <limit effort="1000" velocity="1000.00" lower="-2.7929" upper="-0.267153" />
    </joint>

     <!-- Contact Sensor -->
  <gazebo reference="rear_left_lower_leg">
    <sensor name="rear_left_lower_leg_contactsensor_sensor" type="contact">
      <always_on>true</always_on>
      <contact>
        <collision>rear_left_lower_leg_fixed_joint_lump__rear_bump_sensor_collision</collision>
      </contact>
      <plugin filename="libgazebo_ros_bumper.so" name="rear_left_lower_leg_plugin">
        <bumperTopicName>rear_left_lower_leg_contact</bumperTopicName>
        <frameName>rear_left_lower_leg</frameName>
      </plugin>
    </sensor>
  </gazebo>

    <transmission name="rear_left_knee_trans">
	  <type>transmission_interface/SimpleTransmission</type>
	  <joint name="rear_left_knee">
          	<hardwareInterface>EffortJointInterface</hardwareInterface>
          </joint>
	  <actuator name="rear_left_knee">
          	<mechanicalReduction>50</mechanicalReduction>
          	<hardwareInterface>EffortJointInterface</hardwareInterface>
	  </actuator>
    </transmission>
<!-- rear_right_hip -->
   <link name="rear_right_hip">
        <visual>
            <geometry>
                <mesh filename="package://rs_description/meshes/rear_right_hip.dae" />
            </geometry>
        </visual>
        <collision>
            <geometry>
                <mesh filename="package://rs_description/meshes/rear_right_hip_collision.stl" />
            </geometry>
        </collision>
        <inertial>
            <mass value="1.5" />
    	    <inertia  ixx="0.0605" ixy="0.0"  ixz="0.0"  iyy="0.0"  iyz="0.0"  izz="0.0" />
    	</inertial>
    </link>

    <joint name="rear_right_hip_x" type="revolute">
        <origin xyz="-0.29785 -0.05500 0.00000" rpy="0 0 0" />
        <axis xyz="1 0 0" />
        <parent link="body" />
        <child link="rear_right_hip" />
        <dynamics damping="0.1" friction="0.1"/>
        <limit effort="1000" velocity="1000.00" lower="-0.78539816339744827899" upper="0.78539816339744827899" />
    </joint>

    <transmission name="rear_right_hip_x_trans">
	  <type>transmission_interface/SimpleTransmission</type>
	  <joint name="rear_right_hip_x">
          	<hardwareInterface>EffortJointInterface</hardwareInterface>
          </joint>
	  <actuator name="rear_right_hip_x">
          	<mechanicalReduction>50</mechanicalReduction>
          	<hardwareInterface>EffortJointInterface</hardwareInterface>
	  </actuator>
    </transmission>
<!-- rear_right_upper_leg -->
    <link name="rear_right_upper_leg">
        <visual>
            <geometry>
                <mesh filename="package://rs_description/meshes/rear_right_upper_leg.dae" />
            </geometry>
        </visual>
        <collision>
            <geometry>
                <mesh filename="package://rs_description/meshes/rear_right_upper_leg_collision.stl" />
            </geometry>
        </collision>
        <inertial>
            <mass value="1.5" />
    	    <inertia  ixx="0.0" ixy="0.0"  ixz="0.0"  iyy="0.05"  iyz="0.0"  izz="0.0" />
    	</inertial>
    </link>

    <joint name="rear_right_hip_y" type="revolute">
        <origin xyz="0.0 -0.110945 0.0" rpy="0 0 0" />
        <axis xyz="0 1 0" />
        <parent link="rear_right_hip" />
        <child link="rear_right_upper_leg" />
        <dynamics damping="0.1" friction="0.1"/>
        <limit effort="1000" velocity="1000.00" lower="-0.89884456477707963539" upper="2.2951079663725435509" />
    </joint>

    <transmission name="rear_right_hip_y_trans">
	  <type>transmission_interface/SimpleTransmission</type>
	  <joint name="rear_right_hip_y">
          	<hardwareInterface>EffortJointInterface</hardwareInterface>
          </joint>
	  <actuator name="rear_right_hip_y">
          	<mechanicalReduction>50</mechanicalReduction>
          	<hardwareInterface>EffortJointInterface</hardwareInterface>
	  </actuator>
    </transmission>
<!-- rear_right_lower_leg -->
    <link name="rear_right_lower_leg">
        <visual>
            <geometry>
                <mesh filename="package://rs_description/meshes/rear_right_lower_leg.dae" />
            </geometry>
        </visual>
        <collision name='rear_right_lower_leg_fixed_joint_lump__rear_bump_sensor'>
            <geometry>
                <mesh filename="package://rs_description/meshes/rear_right_lower_leg_collision.stl" />
            </geometry>
        </collision>
        <inertial>
            <mass value="1.0" />
    	    <inertia  ixx="0.0" ixy="0.0"  ixz="0.0"  iyy="0.045"  iyz="0.0"  izz="0.0" />
    	</inertial>
    </link>

    <joint name="rear_right_knee" type="revolute">
        <origin xyz="0.025 0.000 -0.3205" rpy="0 0 0" />
        <axis xyz="0 1 0" />
        <parent link="rear_right_upper_leg" />
        <child link="rear_right_lower_leg" />
        <dynamics damping="0.1" friction="0.1"/>
        <limit effort="1000" velocity="1000.00" lower="-2.7929" upper="-0.257725" />
    </joint>

  <!-- Contact Sensor -->
  <gazebo reference="rear_right_lower_leg">
    <sensor name="rear_right_lower_leg_contactsensor_sensor" type="contact">
      <always_on>true</always_on>
      <contact>
        <collision>rear_right_lower_leg_fixed_joint_lump__rear_bump_sensor_collision</collision>
      </contact>
      <plugin filename="libgazebo_ros_bumper.so" name="rear_right_lower_leg_plugin">
        <bumperTopicName>rear_right_lower_leg_contact</bumperTopicName>
        <frameName>rear_right_lower_leg</frameName>
      </plugin>
    </sensor>
  </gazebo>

    <transmission name="rear_right_knee_trans">
	  <type>transmission_interface/SimpleTransmission</type>
	  <joint name="rear_right_knee">
          	<hardwareInterface>EffortJointInterface</hardwareInterface>
          </joint>
	  <actuator name="rear_right_knee">
          	<mechanicalReduction>50</mechanicalReduction>
          	<hardwareInterface>EffortJointInterface</hardwareInterface>
	  </actuator>
    </transmission>

    <gazebo>
    	<plugin name="gazebo_ros_control" filename="libgazebo_ros_control.so">
<!--    	<robotNamespace>/spot1</robotNamespace>-->
  	</plugin>
    </gazebo>
</robot>

